Workbook
Name Controller_List: OFFSET('[1]Room Schedule'!$BC$1,0,0,COUNTA('[1]Room Schedule'!$BC$1:$BC$65536),1)
Name export_5: 'Rapid Archive Schedule'!#REF!

Sheet Rapid Archive Schedule
A1: RAC-4096 | B1: RAC-4112 | C1: RAC-4128 | D1: RAC-4144 | E1: RAC-4160 | F1: RAC-4166 | G1: RAC-4170 | H1: RAC-4176 | I1: RAC-4192 | J1: RAC-4208 | K1: RAC-4224 | L1: RAC-4240 | M1: RAC-4256 | N1: RAC-4272 | O1: RAC-4288 | P1: RAC-4304 | Q1: RAC-4311 | R1: RAC-4320 | S1: RAC-4336 | T1: RAC-4352 | U1: RAC-4368 | V1: RAC-4384 | W1: RAC-4400 | X1: RAC-4416 | Y1: RAC-4432 | Z1: RAC-4448
A2: v3
A3: Space Information | D3: Network / Equipment Tree Information | J3: Network Information (MSTP and IP) | X3: Definitions and Templates | Z3: Parameters
A4: Site/Building/Floor (Required) | B4: Room Number (Optional) | C4: Leaf Space (e.g. Room) (Required) | D4: Device Name (Required) | E4: Device FQR Reference (Required) | F4: Device Description (Optional) | G4: Equipment Name (Required) | H4: Served By Equipment Name (Optional) | I4: Controller Part # (Optional) | J4: Engine Name (Required) | K4: Trunk Name (Required) | L4: Controller Host Name (Future) | M4: JCI MAC Address | N4: IP Controller Number | O4: ZIGBEE PAN Offset | P4: Instance # (BACoid) | Q4: N2Address | R4: DHCP Enabled | S4: IP Address | T4: Subnet Mask | U4: IP Router | V4: ETH-1 (Optional) | W4: ETH-2 (Optional) | X4: Equipment Definition Name | Y4: Controller Template Name
D5: Attribute ID
D6: Attribute Type

Sheet Column Descriptions
A1: Rows 1 and 2 New at Release 13 | B1: - Row 1 contains "column codes" that are used by the SCT Import / Merge process to identify the source of data from the RAC Worksheet. - These new "column codes" allow you to insert user defined columns anywhere in the RAC worksheets without effecting the import / merge interactions between a worksheet and the SCT RAC view. - Note that and Export from SCT into a RAC Spreadsheet must be executed into a worksheet that has not been altered (still some discussion on how this workflow should happen - Column 2 contains the version # of the RAC Workbook. Potential Video Link showing ideas for adding columns and working with the RAC Spreadsheet
A3: Group | B3: Column Heading | C3: RAC Use | D3: New Site Process Description and Notes - SCT RAC View in Edit Mode for Import Process from RAC Spreadsheet (Video Link) | E3: Modify Site Process Description and Notes - SCT RAC View without Edit Mode enabled to Export into RAC Spreadsheet (Video Link) | F3: Summary of Changes at SCT 13
A4: Space Information | B4: Site/Building/Floor | C4: Yes | D4: - Enter the Spaces Tree hierarchy that precedes the Leaf Space column to auto create the Spaces Tree. For Example, BE Headquarters/Campus 507/Building 9/Floor 2 creates a four space parent hierarchy of BE Headquarters, Campus 507, Building 9, Floor 2 before the Leaf Space is appended. - Note that the / is used as the delimiter between the Spaces - See the "New Site Examples" worksheet for best practices on setting up Space and Equipment Relationships. | E4: - The basic Site/Building/Floor information could be roughed in as a starting point for the Modify Process. During the Merge Process from the RAC Spreadsheet, the Site / Building / Floor information can be entered into the spreadsheet but it will not be re-created during the merge. | F4: None
B5: Room Number | C5: Reference Only | D5: - The Room Number is provided as a reference for Room leaf spaces based on information typically found on the mechanical prints during the creation of a new site. - Note: The updated "Facility Menu" Item in SCT allows you to export the complete Spaces Tree into a spreadsheet. The official Space labels can be added in the spreadsheet and merged back into the Spaces Tree. Link to Video Example of Editing Spaces Tree | E5: This column would typically not be used when adding Spaces and Equipment to an existing archive. | F5: New workflow process to re-label Space Names using the Update Object Label feature.
B6: Leaf Space (e.g. Room) | C6: Yes | D6: - Enter the Leaf Space associated to the Site/Building/Floor hierarchy that is associated to the Equipment being created for the leaf space. - See the "New Site Examples" worksheet for how terminal unit, AHU and plant equipment schedules Space and Equipment relationships are created against the Leaf Space. - Note: The data populated in this column is added to the field contollers description attribute during the creation of a new Site for MUI. - Note: The updated Facility Menu Item in SCT allows you to export all the Space Labels into a spreadsheet. With this new feature, Space labels can be added in the spreadsheet and quickly merged into the Space Tree. This allows you to start a new project with the Mechanical print Room Numbers as the Leaf Space and use the Update Object Labels feature to quickly update all the space names once the end customer has created their official naming strategy. Link to Video Example of Editing Spaces Tree | E6: - During the process of exporting an Engine into the RAC Spreadsheet, all the Space information can be entered and merged back into the Rapid Archive SCT view. | F6: New workflow process to re-label Space Names using the Update Object Label feature.
A7: All Items / Equipment Tree Information | B7: Device Name | C7: Yes | D7: - At Release 13, this entry now creates only the Device Name in the All Items / Network Trees. - A seperate Equipment Name column entry has been added to the RAC spreadsheet so that unique labels can be created for the Devices in the All Items Tree and the Equipment in SCT's Equipment tab and the MUI Equipment Name. - Under the updated Facility Menu Item in SCT, the Update Object Labels feature allows you to export all the Device Labels into a spreadsheet and update any Device Names before a merge of the Device Names is applied. Link to Video Example of Editing Device Labels and Device Desriptions | E7: - At Release 13, the Export function from SCT RAC to the RAC Spreadsheet will poplulate the Device Names. - You can add an Equipment Name in the new column added at Release 13. - Under the updated Facility Menu Item in SCT, the Update Object Labels feature allows you to export all the Device Labels into a spreadsheet and update any Device Names before a merge of the Device Names is applied. Link to Video Example of Editing Device Labels and Device Descriptions | F7: New - the Device and Equipment Name are unique at Release 13
B8: Device FQR Reference | C8: Yes | D8: - Enter the Controller's FQR as you want it to appear in the SCT and SMP UI and tool tips. - This column populates the Item Reference name with the fully qualified reference in the Rapid Archive Wizard. | E8: - At Release 13, the Export function from SCT RAC to the RAC Spreadsheet will poplulate the Device FQR Reference. | F8: New - this used to say Device and Equipment FQR
B9: Device Description | C9: Yes | D9: - This column has been added at Release 13 - For new jobs, the RAC process will add Descriptions to the Device. | E9: - This column has been added at Release 13 - The Descriptions from the devices will be exported into the RAC sheet for use as a reference | F9: New at Release 13
B10: Equipment Name | C10: Yes | D10: - This column has been added at Release 13 - You can now create unique Device Names and Equipment Names during the RAC process. | E10: - This column has been added at Release 13 - You can now create unique Device Names and Equipment Names during the RAC process. | F10: New - the Device and Equipment Name are unique at Release 13
B11: Served By Equipment Name | C11: Yes (Optional) | D11: - Enter the exact name of the pre-existing equipment that serves downstream equipment (e.g. the equipment name for an AHU serving a VAV Box) - This column populates the Served By relationship in the SCT Rapid Archive Wizard. - This serving equipment name(s) must already be created in the Equipment Tree of the SCT archive or the serving relationship is not created through the Rapid Archive Wizard process. | E11: - Enter the exact name of the pre-existing equipment that serves downstream equipment (e.g. the equipment name for an AHU serving a VAV Box) - This column populates the Served By relationship in the Rapid Archive Wizard. - This serving equipment name(s) must already be created in the Equipment Tree of the SCT archive or the serving relationship is not created through the Rapid Archive Wizard process. | F11: New - Multiple Served by Equipment Names can be entered with a $$ delimiter
B12: Controller Part # | C12: Reference Only | D12: - The Controller Part # column is provided as a local reference that does not populate any columns in the Rapid Archive Wizard. | E12: - The Controller Part # column is provided as a local reference that does not populate any columns in the Rapid Archive Wizard.
A13: Network Information (MSTP and IP) | B13: Engine Name | C13: Yes | D13: - Enter the parent NAE name exactly as it appears in the All Items Tree in SCT. - The parent NAE to your controller must already be created in the SCT archive before the Rapid Archive Wizard process is run. | E13: - The Engine Name will be exported to the RAC spreadsheet
B14: Trunk Name | C14: Yes | D14: - Enter the Trunk Name(s) of the integrations under the Engine Names. - The trunk for your controller must already be created in All Items Tree of the SCT Archive under the desired Engine or the integration relationship will not be created through the Rapid Archive Wizard. - For MSTP Trunks, remember to set the Trunk Number in the Hardware Tab of the MSTP Integration when the trunk is initially created. The Rapid Archive Wizard supports both hardware and remote field bus assignments. MSTP trunks will also have their own JCI MAC Address column per device that needs to be populated. - For IP Trunks, you can only create and name one IP integration per engine. IP trunks will also have their own IP Controller Number column per device that needs to be populated. | E14: - The Trunk Name or Names will be exported to the RAC spreadsheet - Note that N2 Integrations are shown in the exported data - When working in the RAC Spreadsheet with the exported data, this column is a good column to filter on when adding data to the other fields. | F14: N2 Integrations are exported
B15: Controller Host Name (Future) | C15: Reference Only | D15: - The Controller Host Name column is provided as a local reference that does not populate any columns in the Rapid Archive Wizard. | E15: - The Controller Host Name column is provided as a local reference that does not populate any columns in the Rapid Archive Wizard.
B16: JCI MAC Address | C16: Yes (Unique for MSTP Integrations) | D16: - The JCI MAC Address is the 8 position dip switch setting on the MSTP controllers or the Rotary switch settings on the Release 10 Field Controllers.. - The uniqueness of the MAC addresses per MSTP integration will be validated during the import into the Rapid Archive Wizard. | E16: - The JCI MAC Address is exported to the RAC spreadsheet | F16: At Release 10, all MSTP field controllers use rotary switches to set the JCI MAC address instead of the 8 position dip switch.
B17: IP Controller Number | C17: Yes (Unique for IP Integrations) | D17: - The Controller Number is the combined value of the rotary switches on the IP Field Controllers - The uniqueness of the Controller Numbers per IP Integration will be validated by the during the import into Rapid Archive Wizard. | E17: - The Controller Number is exported to the RAC spreadsheet
B18: ZigBee PANs Offset | C18: Reference Only | D18: - The ZigBee PANs Offset column is provided as a local reference column for users configuring a WNC mesh and does not populate any columns in the Rapid Archive Wizard. - The WNC integration is setup as a Remote Field Bus integration | E18: - Since this is a reference field only, nothing is exported into the RAC spreadsheet
B19: Instance Number (BACoid) | C19: Yes (Optional) | D19: - It is recommended to leave this column blank. During the RAC import process, unique instance numbers will be automatically be created that are unique to the site archive you are working in. - When this column is populated, the RAC import process only validates Instance Number uniqueness for the new devices being added - not against devices that already exist in the archive. - This column populates the Instance Number column in the Rapid Archive Wizard. | E19: - The Instance Number is exported to the RAC spreadsheet
B20: N2 Address | C20: Yes - Only on Export | D20: - Not used in New Site Creation | E20: - The Export process will add the N2 address for the N2 Integrations | F20: new at Release 13
B21: DHCP Enabled | C21: Yes (Unique for IP Integrations) | D21: - Enter True or False to enable or disable DHCP for each IP controller. - When set to True, the IP Address, Subnet Mask and IP Router columns column can be left blank. - When set to False, the IP Address, Subnet Mask and IP Router columns in the RAC Spreadsheet must be populated. | E21: - This value is exported to the RAC spreadsheet
B22: IP Address | C22: Yes (Only when DHCP Enabled = False) | D22: - When DHCP Enabled is set to True, this column can be blank. - When DHCP Enabled is set to False, the IP Address, Subnet Mask and IP Router columns in the RAC Spreadsheet must be populated. | E22: - This value is exported to the RAC spreadsheet
B23: Subnet Mask | C23: Yes (Only when DHCP Enabled = False) | D23: - When DHCP Enabled is set to True, this column can be blank. - When DHCP Enabled is set to False, the IP Address, Subnet Mask and IP Router columns in the RAC Spreadsheet must be populated. | E23: - This value is exported to the RAC spreadsheet
B24: IP Router | C24: Yes (Only when DHCP Enabled = False) | D24: - When DHCP Enabled is set to True, this column can be blank. - When DHCP Enabled is set to False, the IP Address, Subnet Mask and IP Router columns in the RAC Spreadsheet must be populated. | E24: - This value is exported to the RAC spreadsheet
B25: ETH-1 | C25: Reference Only | D25: - The ETH-1 Column is provided as a reference to show how the IP trunk cabling connections are made. If a daisy chain network is created, the ETH-1 and EHT-2 columns can be used to show how the daisy chain was created. | E25: - Since this is a reference field only, nothing is exported into the RAC spreadsheet
B26: ETH-2 | C26: Reference Only | D26: - The ETH-1 Column is provided as a reference to show how the IP trunk cabling connections are made. If a daisy chain network is created, the ETH-1 and EHT-2 columns can be used to show how the daisy chain was created. | E26: - Since this is a reference field only, nothing is exported into the RAC spreadsheet
A27: Definitions and Templates | B27: Equipment Definition Name | C27: Reference Only in New Site Creation Required when updating existing sites with Spaces and Equipment | D27: - This is an optional / reference field for the new Site Process - The Equipment Definitions must be entered in SCT Equipment Folder and be referenced in a Controller Template prior to executing the Rapid Archive Wizard. The Equipment Definition creates the Equipment Instances in the SCT Equipment tab when the Rapid Archive Wizard is saved. Other Tips - It is recommended that one Equipment Definition be used to create all the Equipment Instances of the same general type. For example, one Single Duct VAV Box Equipment Definition could be created for Single Duct VAV Boxes that are cooling only, cooling with reheat or fan powered. - Under the Facility Menu Item, the new Prepare Rapid Archive process allows you to quickly start the workflow to create a Controller Template from a caf file and build an associated Equipment Definition from the Controller Template - Note that an Equipment Definition can be quickly created from a Controller Template at Release 13 (right cliek menu item on the controller template) | E27: - This is a required field in the RAC Spreadsheet once the export has been made - The Equipment Definitions must be entered in the SCT Equipment Folder before the merge process is initated. | F27: New Workflows to quickly create an Equipment Defintion from a Controller Template Link to future Videos that show the updates to updated workflows
B28: Controller Template Name | C28: Required in New Site Creation Not Required when updating existing sites with Spaces and Equipment | D28: - This is a required field in the RAC Spreadsheet - The Controller Template also needs to include the reference to the associated Equipment Definition. - Enter the Controller Template name as displayed in the SCT UI. - This column populates the Controller Template column in the SCT Rapid Archive View. - Only Controller Templates with a Equipment Definitions reference will create Equipment Instances. - The Controller Templates for a site's archive need to be defined and added to the archive before the RAC Schedule is imported. - Remember to setup the Point Name Display attributes in the Controller Template to match the desired Point Naming strategy for your site. - The Metasys Field Controllers, the Controller Template should also include the extention to the caf Resource file used to build the points in the Template. Once the RAC Process is run, all the field devices created from the controller template will include a caf resource file that has the Updated Parameters in the columns following the Controller Template Name. | E28: - This field is not used at all in the RAC Spreadsheet during a Modify Site Process | F28: New Workflows to quickly create an Equipment Defintion from a Controller Template Link to future Videos that show the updates to updated workflows
A29: Parameters | B29: See Parameter Worksheet Examples | C29: Yes (Optional) | D29: Example Parameter Sheets are provided as part of this spreadsheet. The example heading data provided in these worksheets can be copied into your master or scratchpad worksheets next to the Controller Template Name column. The examples provided are for VAV Box parameters like Box Areas, k-factors and CFM setpoints. The parameter sheet values can be created from the CCT Trunk Utility Template Files. | E29: The Parameters feature is not used during the Modify Site Process.

Sheet J.R. Instructions
A1: RAC-4096 | B1: RAC-4112 | C1: RAC-4128 | D1: RAC-4144 | E1: RAC-4160 | F1: RAC-4166 | G1: RAC-4170 | I1: RAC-4176 | K1: RAC-4192 | L1: RAC-4208 | M1: RAC-4224 | N1: RAC-4240 | O1: RAC-4256 | P1: RAC-4272 | Q1: RAC-4288 | R1: RAC-4304 | S1: RAC-4311 | T1: RAC-4320 | U1: RAC-4336 | V1: RAC-4352 | W1: RAC-4368 | X1: RAC-4384 | Y1: RAC-4400 | Z1: RAC-4416 | AA1: RAC-4432 | AC1: RAC-4448
A2: v3
A3: Space Information | D3: Network / Equipment Tree Information | L3: Network Information (MSTP and IP) | Z3: Definitions and Templates | AB3: Sensor | AC3: Parameters
A4: Site/Building/Floor (Required) | B4: Room Number (Optional) | C4: Leaf Space (e.g. Room) (Required) | D4: Device Name (Required) | E4: Device FQR Reference (Required) | F4: Device Description (Optional) | G4: Equipment Name (Required) | H4: Mechanical Drawing | I4: Served By Equipment Name (Optional) | J4: JCI Ctrl Dwg No. | K4: Controller Part # (Optional) | L4: Engine Name (Required) | M4: Trunk Name (Required) | N4: Controller Host Name (Future) | O4: JCI MAC Address | P4: IP Controller Number | Q4: ZIGBEE PAN Offset | R4: Instance # (BACoid) | S4: N2Address | T4: DHCP Enabled | U4: IP Address | V4: Subnet Mask | W4: IP Router | X4: ETH-1 (Optional) | Y4: ETH-2 (Optional) | Z4: Equipment Definition Name (Optional) | AA4: Controller Template Name (Required) | AB4: Code No | AC4: Box Heat | AD4: Supplemental Heat | AE4: Inlet Size (inches) | AF4: SA-AREA | AG4: SA-KFACTOR | AH4: CLG-MAXFLOW | AI4: CLGOCC-MINFLOW | AJ4: HTGOCC-MAXFLOW | AK4: HTGOCC-MINFLOW | AL4: Comments
D5: Attribute ID | AF5: AV3111 | AG5: AV3112 | AH5: AV3108 | AI5: AV3109 | AK5: AV3110
D6: Attribute Type | AF6: Default Value | AG6: Default Value | AH6: Default Value | AI6: Default Value | AJ6: Default Value | AK6: Default Value
A7: Template Instructions - This Template is based v3 of the RAC Schedule Master. When a Master is issued, a new Template should be generated using the new Master. Insert the required columns, update the equations as needed - This Template is setup for Hardware engineering to be a starting place for Software engineering. Some of the fields are specific to Software and have no impact on Hardware but can be used to setup Software for success - The equations for Device Name, Device FQR Reference, and Device Description are based off a specific customer's standard. Adapt the equations as needed to meet the project customer's standards - For information on the functions used, refer to Microsoft Help or O365 training - Comments on each cell help explain the specific use and updating requirements of the information in the cells | E7: 1. Copy the Manufacturer sheet from this workbook to the project RAC Schedule 2. Copy the columns from New Empty Scratchpad which get added to the RAC Schedule and paste them in the proper locations 3. Copy the formulas from this page to the New Empty Scratchpad in the project RAC Schedule. 4. Paste the functions (only the functions) in the first row used for the schedule data. 5. Choose the Manufacturer for the boxes and complete the table as noted below.
A8: Plant Systems | G8: .
A9: MPL | C9: MillRd | D9: =_xlfn.CONCAT("MRs-",G9) -> MRs-HWS | E9: =_xlfn.CONCAT(RIGHT(L9,2),RIGHT(M9,1),MID(K9,4,2),"0",RIGHT(R9,2)) -> 031CG004 | F9: =_xlfn.CONCAT(D9," - ",C9,IF(ISBLANK(B9),"",_xlfn.CONCAT(" Rm ",B9))) -> MRs-HWS - MillRd | G9: HWS | H9: M3.1 | J9: 01.01.01 | K9: M4-CGM04060-0 | L9: S3-SNE03 | M9: FC-1 | O9: 4 | R9: =1003100+O9 -> 1003104
A10: Air Systems
A11: MPL/MillRd | C11: Floor 1 | D11: =_xlfn.CONCAT("MR-",G11) -> MR-AHU-1 | E11: =_xlfn.CONCAT(RIGHT(L11,2),RIGHT(M11,1),MID(K11,4,2),"0",RIGHT(R11,2)) -> 031CG005 | F11: =_xlfn.CONCAT(D11," - ",C11,IF(ISBLANK(B11),"",_xlfn.CONCAT(" Rm ",B11))) -> MR-AHU-1 - Floor 1 | G11: AHU-1 | H11: M2.1 | I11: HWS,CHWS | J11: 02.01.01 | K11: M4-CGM09090-0 | L11: S3-SNE03 | M11: FC-1 | O11: 5 | R11: =1003100+O11 -> 1003105
A12: Terminal Systems
A13: MPL/MillRd/Floor 1 | B13: 150A | C13: Public Vestibule | D13: =_xlfn.CONCAT("MR-",G13) -> MR-VAV-1 | E13: =_xlfn.CONCAT(RIGHT(L13,2),RIGHT(M13,1),MID(K13,4,2),"0",RIGHT(R13,2)) -> 031CV006 | F13: =_xlfn.CONCAT(D13," - ",C13,IF(ISBLANK(B13),"",_xlfn.CONCAT(" Rm ",B13))) -> MR-VAV-1 - Public Vestibule Rm 150A | G13: VAV-1 | H13: M2.1 | I13: AHU-1, HWS | J13: 03.02.01 | K13: M4-CVM03050-0 | L13: S3-SNE03 | M13: FC-1 | O13: 6 | R13: =1003100+O13 -> 1003106 | Z13: VAV | AA13: VAV-RH | AB13: NSB8BTN245-0 | AC13: =IF(AND(NOT(ISBLANK(AA13)),NOT(EXACT(AA13,"VAV-CLG"))),TRUE,FALSE) -> TRUE | AD13: =IF(EXACT(AA13,"VAV-RAD"),TRUE,FALSE) -> FALSE | AE13: 4 | AF13: =VLOOKUP($AE13,Manufacturer!$B$2:$E$22,3) -> 0.09 | AG13: =VLOOKUP($AE13,Manufacturer!$B$2:$E$22,4) -> 1.63 | AH13: 100 | AI13: 100 | AJ13: 100 | AK13: 100
A14: MPL/MillRd/Floor 1 | B14: 150A | C14: Public Vestibule | D14: =_xlfn.CONCAT("MR-",G14) -> MR-VAV-1 | E14: =_xlfn.CONCAT(RIGHT(L14,2),RIGHT(M14,1),MID(K14,4,2),"0",RIGHT(R14,2)) -> 031CV007 | F14: =_xlfn.CONCAT(D14," - ",C14,IF(ISBLANK(B14),"",_xlfn.CONCAT(" Rm ",B14))) -> MR-VAV-1 - Public Vestibule Rm 150A | G14: VAV-1 | H14: M2.1 | I14: AHU-1, HWS | J14: 03.02.01 | K14: M4-CVM03050-0 | L14: S3-SNE03 | M14: FC-1 | O14: 7 | R14: =1003100+O14 -> 1003107 | Z14: VAV | AA14: VAV-CLG | AB14: NSB8BTN245-0 | AC14: =IF(AND(NOT(ISBLANK(AA14)),NOT(EXACT(AA14,"VAV-CLG"))),TRUE,FALSE) -> FALSE | AD14: =IF(EXACT(AA14,"VAV-RAD"),TRUE,FALSE) -> FALSE | AE14: 8 | AF14: =VLOOKUP($AE14,Manufacturer!$B$2:$E$22,3) -> 0.35 | AG14: =VLOOKUP($AE14,Manufacturer!$B$2:$E$22,4) -> 2.39 | AH14: 525 | AI14: 525
A15: MPL/MillRd/Floor 1 | B15: 150A | C15: Public Vestibule | D15: =_xlfn.CONCAT("MR-",G15) -> MR-VAV-1 | E15: =_xlfn.CONCAT(RIGHT(L15,2),RIGHT(M15,1),MID(K15,4,2),"0",RIGHT(R15,2)) -> 031CV008 | F15: =_xlfn.CONCAT(D15," - ",C15,IF(ISBLANK(B15),"",_xlfn.CONCAT(" Rm ",B15))) -> MR-VAV-1 - Public Vestibule Rm 150A | G15: VAV-1 | H15: M2.1 | I15: AHU-1, HWS | J15: 03.02.01 | K15: M4-CVM03050-0 | L15: S3-SNE03 | M15: FC-1 | O15: 8 | R15: =1003100+O15 -> 1003108 | Z15: VAV | AA15: VAV-RAD | AB15: NSB8BTN245-0 | AC15: =IF(AND(NOT(ISBLANK(AA15)),NOT(EXACT(AA15,"VAV-CLG"))),TRUE,FALSE) -> TRUE | AD15: =IF(EXACT(AA15,"VAV-RAD"),TRUE,FALSE) -> TRUE | AE15: 4 | AF15: =VLOOKUP($AE15,Manufacturer!$B$2:$E$22,3) -> 0.09 | AG15: =VLOOKUP($AE15,Manufacturer!$B$2:$E$22,4) -> 1.63 | AH15: 100 | AI15: 30 | AJ15: 65 | AK15: 30
A16: MPL/MillRd/Floor 1 | B16: 150A | C16: Public Vestibule | D16: =_xlfn.CONCAT("MR-",G16) -> MR-VAV-1 | E16: =_xlfn.CONCAT(RIGHT(L16,2),RIGHT(M16,1),MID(K16,4,2),"0",RIGHT(R16,2)) -> 031CV009 | F16: =_xlfn.CONCAT(D16," - ",C16,IF(ISBLANK(B16),"",_xlfn.CONCAT(" Rm ",B16))) -> MR-VAV-1 - Public Vestibule Rm 150A | G16: VAV-1 | H16: M2.1 | I16: AHU-1, HWS | J16: 03.02.01 | K16: M4-CVM03050-0 | L16: S3-SNE03 | M16: FC-1 | O16: 9 | R16: =1003100+O16 -> 1003109 | Z16: VAV | AA16: VAV-RAD | AB16: NSB8BTN245-0 | AC16: =IF(AND(NOT(ISBLANK(AA16)),NOT(EXACT(AA16,"VAV-CLG"))),TRUE,FALSE) -> TRUE | AD16: =IF(EXACT(AA16,"VAV-RAD"),TRUE,FALSE) -> TRUE | AE16: 10 | AF16: =VLOOKUP($AE16,Manufacturer!$B$2:$E$22,3) -> 0.55 | AG16: =VLOOKUP($AE16,Manufacturer!$B$2:$E$22,4) -> 2.31 | AH16: 700 | AI16: 165 | AJ16: 433 | AK16: 165
A17: MPL/MillRd/Floor 1 | B17: 150A | C17: Public Vestibule | D17: =_xlfn.CONCAT("MR-",G17) -> MR-VAV-1 | E17: =_xlfn.CONCAT(RIGHT(L17,2),RIGHT(M17,1),MID(K17,4,2),"0",RIGHT(R17,2)) -> 031CV010 | F17: =_xlfn.CONCAT(D17," - ",C17,IF(ISBLANK(B17),"",_xlfn.CONCAT(" Rm ",B17))) -> MR-VAV-1 - Public Vestibule Rm 150A | G17: VAV-1 | H17: M2.1 | I17: AHU-1, HWS | J17: 03.02.01 | K17: M4-CVM03050-0 | L17: S3-SNE03 | M17: FC-1 | O17: 10 | R17: =1003100+O17 -> 1003110 | Z17: VAV | AA17: VAV-RH | AB17: NSB8BTN245-0 | AC17: =IF(AND(NOT(ISBLANK(AA17)),NOT(EXACT(AA17,"VAV-CLG"))),TRUE,FALSE) -> TRUE | AD17: =IF(EXACT(AA17,"VAV-RAD"),TRUE,FALSE) -> FALSE | AE17: 6 | AF17: =VLOOKUP($AE17,Manufacturer!$B$2:$E$22,3) -> 0.2 | AG17: =VLOOKUP($AE17,Manufacturer!$B$2:$E$22,4) -> 3.07 | AH17: 350 | AI17: 85 | AJ17: 218 | AK17: 85

Sheet Manufacturer
V1: Anemostat | Y1: =F24 -> 5 | Z1: =G24 -> 6
D2: Titus | F2: =VLOOKUP($D$2,$V$1:$Z$17,4) -> 31 | G2: =VLOOKUP($D$2,$V$1:$Z$17,5) -> 32 | V2: Carnes Cross-Flow | Y2: =J24 -> 9 | Z2: =K24 -> 10
D3: If you have an unknown manufacture, or the manufacturre is not listed in this sheet, use the K Factors below. | V3: Carnes Standard | Y3: =H24 -> 7 | Z3: =I24 -> 8
B4: VAV Box Duct Size | D4: Area | E4: Average K Factor | V4: Carrier | Y4: =L24 -> 11 | Z4: =M24 -> 12
B5: 4 | D5: =VLOOKUP($B5,$B$28:$AK$45,$F$2) -> 0.09 | E5: =VLOOKUP($B5,$B$28:$AK$45,$G$2) -> 1.63 | V5: EH Price | Y5: =N24 -> 13 | Z5: =O24 -> 14
B6: 5 | D6: =VLOOKUP($B6,$B$28:$AK$45,$F$2) -> 0.14 | E6: =VLOOKUP($B6,$B$28:$AK$45,$G$2) -> 1.95 | V6: Enviromental Tech 45 (Largo) | Y6: =P24 -> 15 | Z6: =Q24 -> 16
B7: 6 | D7: =VLOOKUP($B7,$B$28:$AK$45,$F$2) -> 0.2 | E7: =VLOOKUP($B7,$B$28:$AK$45,$G$2) -> 3.07 | V7: Enviromental Tech 90 (Largo) | Y7: =R24 -> 17 | Z7: =S24 -> 18
B8: 7 | D8: =VLOOKUP($B8,$B$28:$AK$45,$F$2) -> 0.27 | E8: =VLOOKUP($B8,$B$28:$AK$45,$G$2) -> 2.57 | V8: Generic (Unknown) | Y8: =D24 -> 3 | Z8: =E24 -> 4
B9: 8 | D9: =VLOOKUP($B9,$B$28:$AK$45,$F$2) -> 0.35 | E9: =VLOOKUP($B9,$B$28:$AK$45,$G$2) -> 2.39 | V9: Krueger | Y9: =T24 -> 19 | Z9: =U24 -> 20
B10: 9 | D10: =VLOOKUP($B10,$B$28:$AK$45,$F$2) -> 0.44 | E10: =VLOOKUP($B10,$B$28:$AK$45,$G$2) -> 2.3 | V10: Metal Industries | Y10: =V24 -> 21 | Z10: =W24 -> 22
B11: 10 | D11: =VLOOKUP($B11,$B$28:$AK$45,$F$2) -> 0.55 | E11: =VLOOKUP($B11,$B$28:$AK$45,$G$2) -> 2.31 | V11: Nailor | Y11: =X24 -> 23 | Z11: =Y24 -> 24
B12: 12 | D12: =VLOOKUP($B12,$B$28:$AK$45,$F$2) -> 0.79 | E12: =VLOOKUP($B12,$B$28:$AK$45,$G$2) -> 2.76 | V12: Redd-i | Y12: =Z24 -> 25 | Z12: =AA24 -> 26
B13: 14 | D13: =VLOOKUP($B13,$B$28:$AK$45,$F$2) -> 1.07 | E13: =VLOOKUP($B13,$B$28:$AK$45,$G$2) -> 2.02 | V13: Temperature Industries | Y13: =AB24 -> 27 | Z13: =AC24 -> 28
B14: 16 | D14: =VLOOKUP($B14,$B$28:$AK$45,$F$2) -> 1.4 | E14: =VLOOKUP($B14,$B$28:$AK$45,$G$2) -> 1.12 | V14: Tempmaster (York) | Y14: =AD24 -> 29 | Z14: =AE24 -> 30
B15: 18 | D15: =VLOOKUP($B15,$B$28:$AK$45,$F$2) -> n/a | E15: =VLOOKUP($B15,$B$28:$AK$45,$G$2) -> n/a | V15: Titus | Y15: =AF24 -> 31 | Z15: =AG24 -> 32
B16: 19 | D16: =VLOOKUP($B16,$B$28:$AK$45,$F$2) -> n/a | E16: =VLOOKUP($B16,$B$28:$AK$45,$G$2) -> n/a | V16: Tuttle and Bailey | Y16: =AH24 -> 33 | Z16: =AI24 -> 34
B17: 20 | D17: =VLOOKUP($B17,$B$28:$AK$45,$F$2) -> 0.78 | E17: =VLOOKUP($B17,$B$28:$AK$45,$G$2) -> 2.19 | V17: VariTrane F-Style | Y17: =AJ24 -> 35 | Z17: =AK24 -> 36
B18: 22 | D18: =VLOOKUP($B18,$B$28:$AK$45,$F$2) -> 0.78 | E18: =VLOOKUP($B18,$B$28:$AK$45,$G$2) -> 2.19
B19: 24 | D19: =VLOOKUP($B19,$B$28:$AK$45,$F$2) -> n/a | E19: =VLOOKUP($B19,$B$28:$AK$45,$G$2) -> n/a
B20: 26 | D20: =VLOOKUP($B20,$B$28:$AK$45,$F$2) -> 1 | E20: =VLOOKUP($B20,$B$28:$AK$45,$G$2) -> 2.57
B21: 30 | D21: =VLOOKUP($B21,$B$28:$AK$45,$F$2) -> n/a | E21: =VLOOKUP($B21,$B$28:$AK$45,$G$2) -> n/a
B22: 40 | D22: =VLOOKUP($B22,$B$28:$AK$45,$F$2) -> 2.67 | E22: =VLOOKUP($B22,$B$28:$AK$45,$G$2) -> 2.22
D24: 3 | E24: 4 | F24: 5 | G24: 6 | H24: 7 | I24: 8 | J24: 9 | K24: 10 | L24: 11 | M24: 12 | N24: 13 | O24: 14 | P24: 15 | Q24: 16 | R24: 17 | S24: 18 | T24: 19 | U24: 20 | V24: 21 | W24: 22 | X24: 23 | Y24: 24 | Z24: 25 | AA24: 26 | AB24: 27 | AC24: 28 | AD24: 29 | AE24: 30 | AF24: 31 | AG24: 32 | AH24: 33 | AI24: 34 | AJ24: 35 | AK24: 36
D25: Generic If you have an unknown manufacture, or the manufacturre is not listed in this sheet, use the K Factors below. | F25: Anemostat | H25: Carnes Standard | J25: Carnes Cross-Flow | L25: Carrier | N25: EH Price SD/FP/DD Inlet Boxes | P25: Environmental Tech. 45 deg travel (Largo) | R25: EnviroTech 90deg Travel (Largo) | T25: Krueger | V25: Metal Industries | X25: Nailor | Z25: Redd-i | AB25: Temperature Industries | AD25: Tempmaster (York) | AF25: Titus | AH25: Tuttle and Bailey | AJ25: VariTrane F-Style Boxes
B26: VAV Box Duct Size
D27: Area | E27: K Factor | F27: Area | G27: K Factor | H27: Area | I27: K Factor | J27: Area | K27: K Factor | L27: Area | M27: K Factor | N27: Area | O27: K Factor | P27: Area | Q27: K Factor | R27: Area | S27: K Factor | T27: Area | U27: K Factor | V27: Area | W27: K Factor | X27: Area | Y27: K Factor | Z27: Area | AA27: K Factor | AB27: Area | AC27: K Factor | AD27: Area | AE27: K Factor | AF27: Area | AG27: K Factor | AH27: Area | AI27: K Factor | AJ27: Area | AK27: K Factor
B28: 4 | D28: =(PI()*(B28/2)^2)/144 -> 0.087266463 | E28: =SUBTOTAL(1,G28,I28,K28,M28,O28,Q28,S28,U28,W28,Y28,AA28,AC28,AE28,AG28,AI28,AK28) -> 1.9955556 | F28: n/a | G28: n/a | H28: n/a | I28: n/a | J28: n/a | K28: n/a | L28: 0.09 | M28: 2.26 | N28: 0.09 | O28: 1 | P28: 0.09 | Q28: 1.71 | R28: 0.08 | S28: 1.63 | T28: 0.09 | U28: 2.32 | V28: n/a | W28: n/a | X28: 0.09 | Y28: 2.92 | Z28: n/a | AA28: n/a | AB28: n/a | AC28: n/a | AD28: n/a | AE28: n/a | AF28: 0.09 | AG28: 1.63 | AH28: 0.09 | AI28: 2.8 | AJ28: 0.09 | AK28: 1.69
B29: 5 | D29: =(PI()*(B29/2)^2)/144 -> 0.13635385 | E29: =SUBTOTAL(1,G29,I29,K29,M29,O29,Q29,S29,U29,W29,Y29,AA29,AC29,AE29,AG29,AI29,AK29) -> 2.1564286 | F29: 0.13 | G29: 3.28 | H29: 0.13 | I29: 2.42 | J29: 0.13 | K29: 2.42 | L29: 0.14 | M29: 2.26 | N29: 0.14 | O29: 1.47 | P29: 0.14 | Q29: 1.69 | R29: 0.13 | S29: 1.66 | T29: 0.14 | U29: 2.31 | V29: n/a | W29: n/a | X29: 0.14 | Y29: 2.99 | Z29: n/a | AA29: n/a | AB29: 0.14 | AC29: 1.62 | AD29: 0.14 | AE29: 1.62 | AF29: 0.14 | AG29: 1.95 | AH29: 0.14 | AI29: 3 | AJ29: 0.14 | AK29: 1.5
B30: 6 | D30: =(PI()*(B30/2)^2)/144 -> 0.19634954 | E30: =SUBTOTAL(1,G30,I30,K30,M30,O30,Q30,S30,U30,W30,Y30,AA30,AC30,AE30,AG30,AI30,AK30) -> 2.391875 | F30: 0.19 | G30: 2.58 | H30: 0.19 | I30: 2.37 | J30: 0.19 | K30: 2.37 | L30: 0.2 | M30: 2.45 | N30: 0.2 | O30: 2.8 | P30: 0.2 | Q30: 1.67 | R30: 0.18 | S30: 2.9 | T30: 0.2 | U30: 2.32 | V30: 0.18 | W30: 1.5 | X30: 0.2 | Y30: 3.08 | Z30: 0.2 | AA30: 2.39 | AB30: 0.2 | AC30: 1.78 | AD30: 0.2 | AE30: 1.78 | AF30: 0.2 | AG30: 3.07 | AH30: 0.2 | AI30: 2.9 | AJ30: 0.2 | AK30: 2.31
B31: 7 | D31: =(PI()*(B31/2)^2)/144 -> 0.26725354 | E31: =SUBTOTAL(1,G31,I31,K31,M31,O31,Q31,S31,U31,W31,Y31,AA31,AC31,AE31,AG31,AI31,AK31) -> 2.3854545 | F31: 0.26 | G31: 2.85 | H31: 0.26 | I31: 2.4 | J31: 0.26 | K31: 2.4 | L31: 0.27 | M31: 2.27 | N31: 0.27 | O31: 2.34 | P31: n/a | Q31: n/a | R31: n/a | S31: n/a | T31: 0.27 | U31: 2.32 | V31: n/a | W31: n/a | X31: 0.27 | Y31: 2.85 | Z31: n/a | AA31: n/a | AB31: 0.27 | AC31: 1.62 | AD31: 0.27 | AE31: 1.62 | AF31: 0.27 | AG31: 2.57 | AH31: 0.27 | AI31: 3 | AJ31: n/a | AK31: n/a
B32: 8 | D32: =(PI()*(B32/2)^2)/144 -> 0.34906585 | E32: =SUBTOTAL(1,G32,I32,K32,M32,O32,Q32,S32,U32,W32,Y32,AA32,AC32,AE32,AG32,AI32,AK32) -> 2.1875 | F32: 0.34 | G32: 2.44 | H32: 0.34 | I32: 2.2 | J32: 0.34 | K32: 2.2 | L32: 0.35 | M32: 2.27 | N32: 0.35 | O32: 2.24 | P32: 0.35 | Q32: 1.61 | R32: 0.33 | S32: 2.52 | T32: 0.35 | U32: 2.33 | V32: 0.33 | W32: 1.46 | X32: 0.35 | Y32: 2.65 | Z32: 0.35 | AA32: 2.89 | AB32: 0.35 | AC32: 1.36 | AD32: 0.35 | AE32: 1.36 | AF32: 0.35 | AG32: 2.39 | AH32: 0.35 | AI32: 2.9 | AJ32: 0.35 | AK32: 2.18
B33: 9 | D33: =(PI()*(B33/2)^2)/144 -> 0.44178647 | E33: =SUBTOTAL(1,G33,I33,K33,M33,O33,Q33,S33,U33,W33,Y33,AA33,AC33,AE33,AG33,AI33,AK33) -> 2.3 | F33: 0.43 | G33: 2.46 | H33: n/a | I33: n/a | J33: n/a | K33: n/a | L33: 0.44 | M33: 2.27 | N33: 0.44 | O33: 2.21 | P33: n/a | Q33: n/a | R33: n/a | S33: n/a | T33: 0.44 | U33: 2.33 | V33: n/a | W33: n/a | X33: 0.44 | Y33: 2.23 | Z33: n/a | AA33: n/a | AB33: n/a | AC33: n/a | AD33: n/a | AE33: n/a | AF33: 0.44 | AG33: 2.3 | AH33: n/a | AI33: n/a | AJ33: n/a | AK33: n/a
B34: 10 | D34: =(PI()*(B34/2)^2)/144 -> 0.54541539 | E34: =SUBTOTAL(1,G34,I34,K34,M34,O34,Q34,S34,U34,W34,Y34,AA34,AC34,AE34,AG34,AI34,AK34) -> 2.1825 | F34: 0.53 | G34: 2.48 | H34: 0.53 | I34: 2.1 | J34: 0.53 | K34: 2.1 | L34: 0.55 | M34: 2.27 | N34: 0.55 | O34: 1.96 | P34: 0.52 | Q34: 1.63 | R34: 0.53 | S34: 2.41 | T34: 0.55 | U34: 2.32 | V34: 0.52 | W34: 1.52 | X34: 0.55 | Y34: 2.42 | Z34: 0.55 | AA34: 2.98 | AB34: 0.55 | AC34: 1.68 | AD34: 0.55 | AE34: 1.68 | AF34: 0.55 | AG34: 2.31 | AH34: 0.55 | AI34: 3 | AJ34: 0.55 | AK34: 2.06
B35: 12 | D35: =(PI()*(B35/2)^2)/144 -> 0.78539816 | E35: =SUBTOTAL(1,G35,I35,K35,M35,O35,Q35,S35,U35,W35,Y35,AA35,AC35,AE35,AG35,AI35,AK35) -> 2.36375 | F35: 0.77 | G35: 2.92 | H35: 0.77 | I35: 2 | J35: 0.77 | K35: 2 | L35: 0.79 | M35: 2.27 | N35: 0.79 | O35: 2.03 | P35: 0.69 | Q35: 1.61 | R35: 0.76 | S35: 2.38 | T35: 0.79 | U35: 2.32 | V35: 0.76 | W35: 1.48 | X35: 0.79 | Y35: 2.52 | Z35: 0.79 | AA35: 2.79 | AB35: 0.79 | AC35: 2.77 | AD35: 0.79 | AE35: 2.77 | AF35: 0.79 | AG35: 2.76 | AH35: 0.79 | AI35: 3 | AJ35: 0.79 | AK35: 2.2
B36: 14 | D36: =(PI()*(B36/2)^2)/144 -> 1.0690142 | E36: =SUBTOTAL(1,G36,I36,K36,M36,O36,Q36,S36,U36,W36,Y36,AA36,AC36,AE36,AG36,AI36,AK36) -> 2.2575 | F36: 1.05 | G36: 2.9 | H36: 1.05 | I36: 2 | J36: 1.05 | K36: 2 | L36: 1.07 | M36: 2.27 | N36: 1.07 | O36: 1.97 | P36: 0.86 | Q36: 1.59 | R36: 1.04 | S36: 2.29 | T36: 1.07 | U36: 2.33 | V36: 1.04 | W36: 1.69 | X36: 1.07 | Y36: 2.35 | Z36: 1.07 | AA36: 2.65 | AB36: 1.07 | AC36: 2.43 | AD36: 1.07 | AE36: 2.43 | AF36: 1.07 | AG36: 2.02 | AH36: 1.07 | AI36: 3 | AJ36: 1.07 | AK36: 2.2
B37: 16 | D37: =(PI()*(B37/2)^2)/144 -> 1.3962634 | E37: =SUBTOTAL(1,G37,I37,K37,M37,O37,Q37,S37,U37,W37,Y37,AA37,AC37,AE37,AG37,AI37,AK37) -> 2.2 | F37: 1.38 | G37: 2.69 | H37: 1.37 | I37: 1.8 | J37: 1.37 | K37: 1.8 | L37: 1.4 | M37: 2.27 | N37: 1.4 | O37: 1.94 | P37: 1.04 | Q37: 1.61 | R37: 1.36 | S37: 2.29 | T37: 1.4 | U37: 2.33 | V37: 1.36 | W37: 1.54 | X37: 1.4 | Y37: 2.34 | Z37: 1.4 | AA37: 2.51 | AB37: 1.4 | AC37: 2.89 | AD37: 1.4 | AE37: 2.89 | AF37: 1.4 | AG37: 1.12 | AH37: 1.4 | AI37: 3 | AJ37: 1.4 | AK37: 2.18
B38: 18 | D38: =(PI()*(B38/2)^2)/144 -> 1.7671459 | E38: =SUBTOTAL(1,G38,I38,K38,M38,O38,Q38,S38,U38,W38,Y38,AA38,AC38,AE38,AG38,AI38,AK38) -> 2.068 | F38: n/a | G38: n/a | H38: n/a | I38: n/a | J38: n/a | K38: n/a | L38: n/a | M38: n/a | N38: n/a | O38: n/a | P38: 1.21 | Q38: 1.59 | R38: 1.74 | S38: 2.43 | T38: n/a | U38: n/a | V38: n/a | W38: n/a | X38: n/a | Y38: n/a | Z38: n/a | AA38: n/a | AB38: 1.77 | AC38: 1.66 | AD38: 1.77 | AE38: 1.66 | AF38: n/a | AG38: n/a | AH38: 2 | AI38: 3 | AJ38: n/a | AK38: n/a
B39: 19 | D39: =(PI()*(B39/2)^2)/144 -> 1.9689496 | E39: =SUBTOTAL(1,G39,I39,K39,M39,O39,Q39,S39,U39,W39,Y39,AA39,AC39,AE39,AG39,AI39,AK39) -> 2.92 | F39: n/a | G39: n/a | H39: n/a | I39: n/a | J39: n/a | K39: n/a | L39: n/a | M39: n/a | N39: n/a | O39: n/a | P39: n/a | Q39: n/a | R39: 2.72 | S39: 2.92 | T39: n/a | U39: n/a | V39: n/a | W39: n/a | X39: n/a | Y39: n/a | Z39: n/a | AA39: n/a | AB39: n/a | AC39: n/a | AD39: n/a | AE39: n/a | AF39: n/a | AG39: n/a | AH39: n/a | AI39: n/a | AJ39: n/a | AK39: n/a
B40: 20 | D40: =(PI()*(B40/2)^2)/144 -> 2.1816616 | E40: =SUBTOTAL(1,G40,I40,K40,M40,O40,Q40,S40,U40,W40,Y40,AA40,AC40,AE40,AG40,AI40,AK40) -> 1.825 | F40: n/a | G40: n/a | H40: n/a | I40: n/a | J40: n/a | K40: n/a | L40: n/a | M40: n/a | N40: n/a | O40: n/a | P40: 1.47 | Q40: 1.61 | R40: n/a | S40: n/a | T40: n/a | U40: n/a | V40: n/a | W40: n/a | X40: n/a | Y40: n/a | Z40: n/a | AA40: n/a | AB40: 2.18 | AC40: 1.75 | AD40: 2.18 | AE40: 1.75 | AF40: 0.78 | AG40: 2.19 | AH40: n/a | AI40: n/a | AJ40: n/a | AK40: n/a
B41: 22 | D41: =(PI()*(B41/2)^2)/144 -> 2.6398105 | E41: =SUBTOTAL(1,G41,I41,K41,M41,O41,Q41,S41,U41,W41,Y41,AA41,AC41,AE41,AG41,AI41,AK41) -> 2.3166667 | F41: n/a | G41: n/a | H41: n/a | I41: n/a | J41: n/a | K41: n/a | L41: 2.64 | M41: 2.13 | N41: n/a | O41: n/a | P41: 1.83 | Q41: 1.6 | R41: 3.55 | S41: 2.65 | T41: 2.67 | U41: 2.33 | V41: n/a | W41: n/a | X41: n/a | Y41: n/a | Z41: n/a | AA41: n/a | AB41: n/a | AC41: n/a | AD41: n/a | AE41: n/a | AF41: 0.78 | AG41: 2.19 | AH41: 2.44 | AI41: 3 | AJ41: n/a | AK41: n/a
...

Sheet New Empty Scratchpad
A1: RAC-4096 | B1: RAC-4112 | C1: RAC-4128 | D1: RAC-4144 | E1: RAC-4160 | F1: RAC-4166 | G1: RAC-4170 | I1: RAC-4176 | K1: RAC-4192 | L1: RAC-4208 | M1: RAC-4224 | N1: RAC-4240 | O1: RAC-4256 | P1: RAC-4272 | Q1: RAC-4288 | R1: RAC-4304 | S1: RAC-4311 | T1: RAC-4320 | U1: RAC-4336 | V1: RAC-4352 | W1: RAC-4368 | X1: RAC-4384 | Y1: RAC-4400 | Z1: RAC-4416 | AA1: RAC-4432 | AC1: RAC-4448
A2: v3 | AJ2: Manufacturer
A3: Space Information | D3: Network / Equipment Tree Information | L3: Network Information (MSTP and IP) | Z3: Definitions and Templates | AB3: Sensor | AC3: Parameters
A4: Site/Building/Floor (Required) | B4: Room Number (Optional) | C4: Leaf Space (e.g. Room) (Required) | D4: Device Name (Required) | E4: Device FQR Reference (Required) | F4: Device Description (Optional) | G4: Equipment Name (Required) | H4: Mechanical Drawing | I4: Served By Equipment Name (Optional) | J4: JCI Ctrl Dwg No. | K4: Controller Part # (Optional) | L4: Engine Name (Required) | M4: Trunk Name (Required) | N4: Controller Host Name (Future) | O4: JCI MAC Address | P4: IP Controller Number | Q4: ZIGBEE PAN Offset | R4: Instance # (BACoid) | S4: N2Address | T4: DHCP Enabled | U4: IP Address | V4: Subnet Mask | W4: IP Router | X4: ETH-1 (Optional) | Y4: ETH-2 (Optional) | Z4: Equipment Definition Name (Optional) | AA4: Controller Template Name (Required) | AB4: Code No | AC4: Box Heat | AD4: Supplemental Heat | AE4: Inlet Size (inches) | AF4: SA-AREA | AG4: SA-KFACTOR | AH4: CLG-MAXFLOW | AI4: CLGOCC-MINFLOW | AJ4: HTGOCC-MINFLOW | AK4: Comments
D5: Attribute ID | AF5: AV3111 | AG5: AV3112 | AH5: AV3108 | AI5: AV3109 | AJ5: AV3110
D6: Attribute Type | AF6: Default Value | AG6: Default Value | AH6: Default Value | AI6: Default Value | AJ6: Default Value
A7: Plant Systems
E8: =_xlfn.CONCAT(RIGHT(L8,2),RIGHT(M8,1),MID(K8,4,2),"0",RIGHT(R8,2)) -> #VALUE! | F8: =_xlfn.CONCAT(D8," - ",C8,IF(ISBLANK(B8),"",_xlfn.CONCAT(" Rm ",B8))) -> - | R8: =IF(AND(O8<>"", P8<>""), "MAC & IP cannot both have values", _xlfn.CONCAT("1000"+RIGHT(L8,2),RIGHT(M8,1),"00")+O8+P8) -> #VALUE! | Z8: CHWS | AA8: CHWS
E9: =_xlfn.CONCAT(RIGHT(L9,2),RIGHT(M9,1),MID(K9,4,2),"0",RIGHT(R9,2)) -> #VALUE! | F9: =_xlfn.CONCAT(D9," - ",C9,IF(ISBLANK(B9),"",_xlfn.CONCAT(" Rm ",B9))) -> - | R9: =IF(AND(O9<>"", P9<>""), "MAC & IP cannot both have values", _xlfn.CONCAT("1000"+RIGHT(L9,2),RIGHT(M9,1),"00")+O9+P9) -> #VALUE! | Z9: HWS | AA9: HWS
A11: Air Systems
E12: =_xlfn.CONCAT(RIGHT(L12,2),RIGHT(M12,1),MID(K12,4,2),"0",RIGHT(R12,2)) -> #VALUE! | F12: =_xlfn.CONCAT(D12," - ",C12,IF(ISBLANK(B12),"",_xlfn.CONCAT(" Rm ",B12))) -> - | R12: =IF(AND(O12<>"", P12<>""), "MAC & IP cannot both have values", _xlfn.CONCAT("1000"+RIGHT(L12,2),RIGHT(M12,1),"00")+O12+P12) -> #VALUE! | Z12: AHU | AA12: AHU
E13: =_xlfn.CONCAT(RIGHT(L13,2),RIGHT(M13,1),MID(K13,4,2),"0",RIGHT(R13,2)) -> #VALUE! | F13: =_xlfn.CONCAT(D13," - ",C13,IF(ISBLANK(B13),"",_xlfn.CONCAT(" Rm ",B13))) -> - | R13: =IF(AND(O13<>"", P13<>""), "MAC & IP cannot both have values", _xlfn.CONCAT("1000"+RIGHT(L13,2),RIGHT(M13,1),"00")+O13+P13) -> #VALUE! | Z13: AHU | AA13: AHU
E14: =_xlfn.CONCAT(RIGHT(L14,2),RIGHT(M14,1),MID(K14,4,2),"0",RIGHT(R14,2)) -> #VALUE! | F14: =_xlfn.CONCAT(D14," - ",C14,IF(ISBLANK(B14),"",_xlfn.CONCAT(" Rm ",B14))) -> - | R14: =IF(AND(O14<>"", P14<>""), "MAC & IP cannot both have values", _xlfn.CONCAT("1000"+RIGHT(L14,2),RIGHT(M14,1),"00")+O14+P14) -> #VALUE! | Z14: AHU | AA14: AHU
A16: Terminal Systems
E17: =_xlfn.CONCAT(RIGHT(L17,2),RIGHT(M17,1),MID(K17,4,2),"0",RIGHT(R17,2)) -> #VALUE! | F17: =_xlfn.CONCAT(D17," - ",C17,IF(ISBLANK(B17),"",_xlfn.CONCAT(" Rm ",B17))) -> - | R17: =IF(AND(O17<>"", P17<>""), "MAC & IP cannot both have values", _xlfn.CONCAT("1000"+RIGHT(L17,2),RIGHT(M17,1),"00")+O17+P17) -> #VALUE! | Z17: VAV | AA17: VAV-RH | AB17: NSB8BTN240-0 | AC17: =IF(AND(NOT(ISBLANK(AA17)),NOT(EXACT(AA17,"VAV-CLG"))),TRUE,FALSE) -> TRUE | AD17: =IF(EXACT(AA17,"VAV-RAD"),TRUE,FALSE) -> FALSE | AE17: 8 | AF17: =VLOOKUP($AE17,Manufacturer!$B$2:$E$22,3) -> 0.35 | AG17: =VLOOKUP($AE17,Manufacturer!$B$2:$E$22,4) -> 2.39 | AH17: 860 | AI17: 500 | AJ17: 500
E18: =_xlfn.CONCAT(RIGHT(L18,2),RIGHT(M18,1),MID(K18,4,2),"0",RIGHT(R18,2)) -> #VALUE! | F18: =_xlfn.CONCAT(D18," - ",C18,IF(ISBLANK(B18),"",_xlfn.CONCAT(" Rm ",B18))) -> - | R18: =IF(AND(O18<>"", P18<>""), "MAC & IP cannot both have values", _xlfn.CONCAT("1000"+RIGHT(L18,2),RIGHT(M18,1),"00")+O18+P18) -> #VALUE! | Z18: VAV | AA18: VAV-RH | AB18: NSB8BTN240-0 | AC18: =IF(AND(NOT(ISBLANK(AA18)),NOT(EXACT(AA18,"VAV-CLG"))),TRUE,FALSE) -> TRUE | AD18: =IF(EXACT(AA18,"VAV-RAD"),TRUE,FALSE) -> FALSE | AE18: 7 | AF18: =VLOOKUP($AE18,Manufacturer!$B$2:$E$22,3) -> 0.27 | AG18: =VLOOKUP($AE18,Manufacturer!$B$2:$E$22,4) -> 2.57 | AH18: 550 | AI18: 350 | AJ18: 350
E19: =_xlfn.CONCAT(RIGHT(L19,2),RIGHT(M19,1),MID(K19,4,2),"0",RIGHT(R19,2)) -> #VALUE! | F19: =_xlfn.CONCAT(D19," - ",C19,IF(ISBLANK(B19),"",_xlfn.CONCAT(" Rm ",B19))) -> - | R19: =IF(AND(O19<>"", P19<>""), "MAC & IP cannot both have values", _xlfn.CONCAT("1000"+RIGHT(L19,2),RIGHT(M19,1),"00")+O19+P19) -> #VALUE! | Z19: VAV | AA19: VAV-RH | AB19: NSB8BTN240-0 | AC19: =IF(AND(NOT(ISBLANK(AA19)),NOT(EXACT(AA19,"VAV-CLG"))),TRUE,FALSE) -> TRUE | AD19: =IF(EXACT(AA19,"VAV-RAD"),TRUE,FALSE) -> FALSE | AE19: 8 | AF19: =VLOOKUP($AE19,Manufacturer!$B$2:$E$22,3) -> 0.35 | AG19: =VLOOKUP($AE19,Manufacturer!$B$2:$E$22,4) -> 2.39 | AH19: 880 | AI19: 360 | AJ19: 360
E20: =_xlfn.CONCAT(RIGHT(L20,2),RIGHT(M20,1),MID(K20,4,2),"0",RIGHT(R20,2)) -> #VALUE! | F20: =_xlfn.CONCAT(D20," - ",C20,IF(ISBLANK(B20),"",_xlfn.CONCAT(" Rm ",B20))) -> - | R20: =IF(AND(O20<>"", P20<>""), "MAC & IP cannot both have values", _xlfn.CONCAT("1000"+RIGHT(L20,2),RIGHT(M20,1),"00")+O20+P20) -> #VALUE! | Z20: VAV | AA20: VAV-RH | AB20: NSB8BTN240-0 | AC20: =IF(AND(NOT(ISBLANK(AA20)),NOT(EXACT(AA20,"VAV-CLG"))),TRUE,FALSE) -> TRUE | AD20: =IF(EXACT(AA20,"VAV-RAD"),TRUE,FALSE) -> FALSE | AE20: 7 | AF20: =VLOOKUP($AE20,Manufacturer!$B$2:$E$22,3) -> 0.27 | AG20: =VLOOKUP($AE20,Manufacturer!$B$2:$E$22,4) -> 2.57 | AH20: 600 | AI20: 220 | AJ20: 220
E21: =_xlfn.CONCAT(RIGHT(L21,2),RIGHT(M21,1),MID(K21,4,2),"0",RIGHT(R21,2)) -> #VALUE! | F21: =_xlfn.CONCAT(D21," - ",C21,IF(ISBLANK(B21),"",_xlfn.CONCAT(" Rm ",B21))) -> - | R21: =IF(AND(O21<>"", P21<>""), "MAC & IP cannot both have values", _xlfn.CONCAT("1000"+RIGHT(L21,2),RIGHT(M21,1),"00")+O21+P21) -> #VALUE! | Z21: VAV | AA21: VAV-RH | AB21: NSB8BTN240-0 | AC21: =IF(AND(NOT(ISBLANK(AA21)),NOT(EXACT(AA21,"VAV-CLG"))),TRUE,FALSE) -> TRUE | AD21: =IF(EXACT(AA21,"VAV-RAD"),TRUE,FALSE) -> FALSE | AE21: 8 | AF21: =VLOOKUP($AE21,Manufacturer!$B$2:$E$22,3) -> 0.35 | AG21: =VLOOKUP($AE21,Manufacturer!$B$2:$E$22,4) -> 2.39 | AH21: 845 | AI21: 420 | AJ21: 420
E22: =_xlfn.CONCAT(RIGHT(L22,2),RIGHT(M22,1),MID(K22,4,2),"0",RIGHT(R22,2)) -> #VALUE! | F22: =_xlfn.CONCAT(D22," - ",C22,IF(ISBLANK(B22),"",_xlfn.CONCAT(" Rm ",B22))) -> - | R22: =IF(AND(O22<>"", P22<>""), "MAC & IP cannot both have values", _xlfn.CONCAT("1000"+RIGHT(L22,2),RIGHT(M22,1),"00")+O22+P22) -> #VALUE! | Z22: VAV | AA22: VAV-RH | AB22: NSB8BTN240-0 | AC22: =IF(AND(NOT(ISBLANK(AA22)),NOT(EXACT(AA22,"VAV-CLG"))),TRUE,FALSE) -> TRUE | AD22: =IF(EXACT(AA22,"VAV-RAD"),TRUE,FALSE) -> FALSE | AE22: 5 | AF22: =VLOOKUP($AE22,Manufacturer!$B$2:$E$22,3) -> 0.14 | AG22: =VLOOKUP($AE22,Manufacturer!$B$2:$E$22,4) -> 1.95 | AH22: 350 | AI22: 150 | AJ22: 150
E23: =_xlfn.CONCAT(RIGHT(L23,2),RIGHT(M23,1),MID(K23,4,2),"0",RIGHT(R23,2)) -> #VALUE! | F23: =_xlfn.CONCAT(D23," - ",C23,IF(ISBLANK(B23),"",_xlfn.CONCAT(" Rm ",B23))) -> - | R23: =IF(AND(O23<>"", P23<>""), "MAC & IP cannot both have values", _xlfn.CONCAT("1000"+RIGHT(L23,2),RIGHT(M23,1),"00")+O23+P23) -> #VALUE! | Z23: VAV | AA23: VAV-RH | AB23: NSB8BTN240-0 | AC23: =IF(AND(NOT(ISBLANK(AA23)),NOT(EXACT(AA23,"VAV-CLG"))),TRUE,FALSE) -> TRUE | AD23: =IF(EXACT(AA23,"VAV-RAD"),TRUE,FALSE) -> FALSE | AE23: 8 | AF23: =VLOOKUP($AE23,Manufacturer!$B$2:$E$22,3) -> 0.35 | AG23: =VLOOKUP($AE23,Manufacturer!$B$2:$E$22,4) -> 2.39 | AH23: 860 | AI23: 400 | AJ23: 400
E24: =_xlfn.CONCAT(RIGHT(L24,2),RIGHT(M24,1),MID(K24,4,2),"0",RIGHT(R24,2)) -> #VALUE! | F24: =_xlfn.CONCAT(D24," - ",C24,IF(ISBLANK(B24),"",_xlfn.CONCAT(" Rm ",B24))) -> - | R24: =IF(AND(O24<>"", P24<>""), "MAC & IP cannot both have values", _xlfn.CONCAT("1000"+RIGHT(L24,2),RIGHT(M24,1),"00")+O24+P24) -> #VALUE! | Z24: VAV | AA24: VAV-RH | AB24: NSB8BTN240-0 | AC24: =IF(AND(NOT(ISBLANK(AA24)),NOT(EXACT(AA24,"VAV-CLG"))),TRUE,FALSE) -> TRUE | AD24: =IF(EXACT(AA24,"VAV-RAD"),TRUE,FALSE) -> FALSE | AE24: 6 | AF24: =VLOOKUP($AE24,Manufacturer!$B$2:$E$22,3) -> 0.2 | AG24: =VLOOKUP($AE24,Manufacturer!$B$2:$E$22,4) -> 3.07 | AH24: 360 | AI24: 90 | AJ24: 90
E25: =_xlfn.CONCAT(RIGHT(L25,2),RIGHT(M25,1),MID(K25,4,2),"0",RIGHT(R25,2)) -> #VALUE! | F25: =_xlfn.CONCAT(D25," - ",C25,IF(ISBLANK(B25),"",_xlfn.CONCAT(" Rm ",B25))) -> - | R25: =IF(AND(O25<>"", P25<>""), "MAC & IP cannot both have values", _xlfn.CONCAT("1000"+RIGHT(L25,2),RIGHT(M25,1),"00")+O25+P25) -> #VALUE! | Z25: VAV | AA25: VAV-RH | AB25: NSB8BTN240-0 | AC25: =IF(AND(NOT(ISBLANK(AA25)),NOT(EXACT(AA25,"VAV-CLG"))),TRUE,FALSE) -> TRUE | AD25: =IF(EXACT(AA25,"VAV-RAD"),TRUE,FALSE) -> FALSE | AE25: 5 | AF25: =VLOOKUP($AE25,Manufacturer!$B$2:$E$22,3) -> 0.14 | AG25: =VLOOKUP($AE25,Manufacturer!$B$2:$E$22,4) -> 1.95 | AH25: 350 | AI25: 150 | AJ25: 150
E26: =_xlfn.CONCAT(RIGHT(L26,2),RIGHT(M26,1),MID(K26,4,2),"0",RIGHT(R26,2)) -> #VALUE! | F26: =_xlfn.CONCAT(D26," - ",C26,IF(ISBLANK(B26),"",_xlfn.CONCAT(" Rm ",B26))) -> - | R26: =IF(AND(O26<>"", P26<>""), "MAC & IP cannot both have values", _xlfn.CONCAT("1000"+RIGHT(L26,2),RIGHT(M26,1),"00")+O26+P26) -> #VALUE! | Z26: VAV | AA26: VAV-RH | AB26: NSB8BTN240-0 | AC26: =IF(AND(NOT(ISBLANK(AA26)),NOT(EXACT(AA26,"VAV-CLG"))),TRUE,FALSE) -> TRUE | AD26: =IF(EXACT(AA26,"VAV-RAD"),TRUE,FALSE) -> FALSE | AE26: 5 | AF26: =VLOOKUP($AE26,Manufacturer!$B$2:$E$22,3) -> 0.14 | AG26: =VLOOKUP($AE26,Manufacturer!$B$2:$E$22,4) -> 1.95 | AH26: 280 | AI26: 80 | AJ26: 80
E27: =_xlfn.CONCAT(RIGHT(L27,2),RIGHT(M27,1),MID(K27,4,2),"0",RIGHT(R27,2)) -> #VALUE! | F27: =_xlfn.CONCAT(D27," - ",C27,IF(ISBLANK(B27),"",_xlfn.CONCAT(" Rm ",B27))) -> - | R27: =IF(AND(O27<>"", P27<>""), "MAC & IP cannot both have values", _xlfn.CONCAT("1000"+RIGHT(L27,2),RIGHT(M27,1),"00")+O27+P27) -> #VALUE! | Z27: VAV | AA27: VAV-RH | AB27: NSB8BTN240-0 | AC27: =IF(AND(NOT(ISBLANK(AA27)),NOT(EXACT(AA27,"VAV-CLG"))),TRUE,FALSE) -> TRUE | AD27: =IF(EXACT(AA27,"VAV-RAD"),TRUE,FALSE) -> FALSE | AE27: 9 | AF27: =VLOOKUP($AE27,Manufacturer!$B$2:$E$22,3) -> 0.44 | AG27: =VLOOKUP($AE27,Manufacturer!$B$2:$E$22,4) -> 2.3 | AH27: 940 | AI27: 580 | AJ27: 580
E28: =_xlfn.CONCAT(RIGHT(L28,2),RIGHT(M28,1),MID(K28,4,2),"0",RIGHT(R28,2)) -> #VALUE! | F28: =_xlfn.CONCAT(D28," - ",C28,IF(ISBLANK(B28),"",_xlfn.CONCAT(" Rm ",B28))) -> - | R28: =IF(AND(O28<>"", P28<>""), "MAC & IP cannot both have values", _xlfn.CONCAT("1000"+RIGHT(L28,2),RIGHT(M28,1),"00")+O28+P28) -> #VALUE! | Z28: VAV | AA28: VAV-RH | AB28: NSB8BTN240-0 | AC28: =IF(AND(NOT(ISBLANK(AA28)),NOT(EXACT(AA28,"VAV-CLG"))),TRUE,FALSE) -> TRUE | AD28: =IF(EXACT(AA28,"VAV-RAD"),TRUE,FALSE) -> FALSE | AE28: 40 | AF28: =VLOOKUP($AE28,Manufacturer!$B$2:$E$22,3) -> 2.67 | AG28: =VLOOKUP($AE28,Manufacturer!$B$2:$E$22,4) -> 2.22 | AH28: 6800 | AI28: 1900 | AJ28: 1900
... E30: =_xlfn.CONCAT(RIGHT(L30,2),RIGHT(M30,1),MID(K30,4,2),"0",RIGHT(R30,2)) -> #VALUE! | F30: =_xlfn.CONCAT(D30," - ",C30,IF(ISBLANK(B30),"",_xlfn.CONCAT(" Rm ",B30))) -> - | R30: =IF(AND(O30<>"", P30<>""), "MAC & IP cannot both have values", _xlfn.CONCAT("1000"+RIGHT(L30,2),RIGHT(M30,1),"00")+O30+P30) -> #VALUE! | Z30: VAV | AA30: VAV-RH | AB30: NSB8BTN240-1 | AC30: =IF(AND(NOT(ISBLANK(AA30)),NOT(EXACT(AA30,"VAV-CLG"))),TRUE,FALSE) -> TRUE | AD30: =IF(EXACT(AA30,"VAV-RAD"),TRUE,FALSE) -> FALSE | AE30: 8 | AF30: =VLOOKUP($AE30,Manufacturer!$B$2:$E$22,3) -> 0.35 | AG30: =VLOOKUP($AE30,Manufacturer!$B$2:$E$22,4) -> 2.39 | AH30: 750 | AI30: 400 | AJ30: 400
E31: =_xlfn.CONCAT(RIGHT(L31,2),RIGHT(M31,1),MID(K31,4,2),"0",RIGHT(R31,2)) -> #VALUE! | F31: =_xlfn.CONCAT(D31," - ",C31,IF(ISBLANK(B31),"",_xlfn.CONCAT(" Rm ",B31))) -> - | R31: =IF(AND(O31<>"", P31<>""), "MAC & IP cannot both have values", _xlfn.CONCAT("1000"+RIGHT(L31,2),RIGHT(M31,1),"00")+O31+P31) -> #VALUE!
E32: =_xlfn.CONCAT(RIGHT(L32,2),RIGHT(M32,1),MID(K32,4,2),"0",RIGHT(R32,2)) -> #VALUE! | F32: =_xlfn.CONCAT(D32," - ",C32,IF(ISBLANK(B32),"",_xlfn.CONCAT(" Rm ",B32))) -> - | R32: =IF(AND(O32<>"", P32<>""), "MAC & IP cannot both have values", _xlfn.CONCAT("1000"+RIGHT(L32,2),RIGHT(M32,1),"00")+O32+P32) -> #VALUE!
E33: =_xlfn.CONCAT(RIGHT(L33,2),RIGHT(M33,1),MID(K33,4,2),"0",RIGHT(R33,2)) -> #VALUE! | F33: =_xlfn.CONCAT(D33," - ",C33,IF(ISBLANK(B33),"",_xlfn.CONCAT(" Rm ",B33))) -> - | R33: =IF(AND(O33<>"", P33<>""), "MAC & IP cannot both have values", _xlfn.CONCAT("1000"+RIGHT(L33,2),RIGHT(M33,1),"00")+O33+P33) -> #VALUE!
E34: =_xlfn.CONCAT(RIGHT(L34,2),RIGHT(M34,1),MID(K34,4,2),"0",RIGHT(R34,2)) -> #VALUE! | F34: =_xlfn.CONCAT(D34," - ",C34,IF(ISBLANK(B34),"",_xlfn.CONCAT(" Rm ",B34))) -> - | R34: =IF(AND(O34<>"", P34<>""), "MAC & IP cannot both have values", _xlfn.CONCAT("1000"+RIGHT(L34,2),RIGHT(M34,1),"00")+O34+P34) -> #VALUE!
E35: =_xlfn.CONCAT(RIGHT(L35,2),RIGHT(M35,1),MID(K35,4,2),"0",RIGHT(R35,2)) -> #VALUE! | F35: =_xlfn.CONCAT(D35," - ",C35,IF(ISBLANK(B35),"",_xlfn.CONCAT(" Rm ",B35))) -> - | R35: =IF(AND(O35<>"", P35<>""), "MAC & IP cannot both have values", _xlfn.CONCAT("1000"+RIGHT(L35,2),RIGHT(M35,1),"00")+O35+P35) -> #VALUE!
E36: =_xlfn.CONCAT(RIGHT(L36,2),RIGHT(M36,1),MID(K36,4,2),"0",RIGHT(R36,2)) -> #VALUE! | F36: =_xlfn.CONCAT(D36," - ",C36,IF(ISBLANK(B36),"",_xlfn.CONCAT(" Rm ",B36))) -> - | R36: =IF(AND(O36<>"", P36<>""), "MAC & IP cannot both have values", _xlfn.CONCAT("1000"+RIGHT(L36,2),RIGHT(M36,1),"00")+O36+P36) -> #VALUE!
A38: Integrations
D39: =_xlfn.CONCAT("",G39) | E39: =_xlfn.CONCAT(RIGHT(L39,2),RIGHT(M39,1),MID(K39,4,2),"0",RIGHT(R39,2)) -> #VALUE! | F39: =_xlfn.CONCAT(D39," - ",C39,IF(ISBLANK(B39),"",_xlfn.CONCAT(" Rm ",B39))) -> - | R39: =IF(AND(O39<>"", P39<>""), "MAC & IP cannot both have values", _xlfn.CONCAT("1000"+RIGHT(L39,2),RIGHT(M39,1),"00")+O39+P39) -> #VALUE! | Z39: VAV
D40: =_xlfn.CONCAT("",G40) | E40: =_xlfn.CONCAT(RIGHT(L40,2),RIGHT(M40,1),MID(K40,4,2),"0",RIGHT(R40,2)) -> #VALUE! | F40: =_xlfn.CONCAT(D40," - ",C40,IF(ISBLANK(B40),"",_xlfn.CONCAT(" Rm ",B40))) -> - | R40: =IF(AND(O40<>"", P40<>""), "MAC & IP cannot both have values", _xlfn.CONCAT("1000"+RIGHT(L40,2),RIGHT(M40,1),"00")+O40+P40) -> #VALUE! | Z40: VAV
D41: =_xlfn.CONCAT("",G41) | E41: =_xlfn.CONCAT(RIGHT(L41,2),RIGHT(M41,1),MID(K41,4,2),"0",RIGHT(R41,2)) -> #VALUE! | F41: =_xlfn.CONCAT(D41," - ",C41,IF(ISBLANK(B41),"",_xlfn.CONCAT(" Rm ",B41))) -> - | R41: =IF(AND(O41<>"", P41<>""), "MAC & IP cannot both have values", _xlfn.CONCAT("1000"+RIGHT(L41,2),RIGHT(M41,1),"00")+O41+P41) -> #VALUE! | Z41: VAV
D42: =_xlfn.CONCAT("",G42) | E42: =_xlfn.CONCAT(RIGHT(L42,2),RIGHT(M42,1),MID(K42,4,2),"0",RIGHT(R42,2)) -> #VALUE! | F42: =_xlfn.CONCAT(D42," - ",C42,IF(ISBLANK(B42),"",_xlfn.CONCAT(" Rm ",B42))) -> - | R42: =IF(AND(O42<>"", P42<>""), "MAC & IP cannot both have values", _xlfn.CONCAT("1000"+RIGHT(L42,2),RIGHT(M42,1),"00")+O42+P42) -> #VALUE! | Z42: VAV
D43: =_xlfn.CONCAT("",G43) | E43: =_xlfn.CONCAT(RIGHT(L43,2),RIGHT(M43,1),MID(K43,4,2),"0",RIGHT(R43,2)) -> #VALUE! | F43: =_xlfn.CONCAT(D43," - ",C43,IF(ISBLANK(B43),"",_xlfn.CONCAT(" Rm ",B43))) -> - | R43: =IF(AND(O43<>"", P43<>""), "MAC & IP cannot both have values", _xlfn.CONCAT("1000"+RIGHT(L43,2),RIGHT(M43,1),"00")+O43+P43) -> #VALUE! | Z43: VAV
D44: =_xlfn.CONCAT("",G44) | E44: =_xlfn.CONCAT(RIGHT(L44,2),RIGHT(M44,1),MID(K44,4,2),"0",RIGHT(R44,2)) -> #VALUE! | F44: =_xlfn.CONCAT(D44," - ",C44,IF(ISBLANK(B44),"",_xlfn.CONCAT(" Rm ",B44))) -> - | R44: =IF(AND(O44<>"", P44<>""), "MAC & IP cannot both have values", _xlfn.CONCAT("1000"+RIGHT(L44,2),RIGHT(M44,1),"00")+O44+P44) -> #VALUE! | Z44: VAV

Sheet Merge Empty Scratchpad
A1: RAC-4096 | B1: RAC-4112 | C1: RAC-4128 | D1: RAC-4144 | E1: RAC-4160 | F1: RAC-4166 | G1: RAC-4170 | H1: RAC-4176 | I1: RAC-4192 | J1: RAC-4208 | K1: RAC-4224 | L1: RAC-4240 | M1: RAC-4256 | N1: RAC-4272 | O1: RAC-4288 | P1: RAC-4304 | Q1: RAC-4311 | R1: RAC-4320 | S1: RAC-4336 | T1: RAC-4352 | U1: RAC-4368 | V1: RAC-4384 | W1: RAC-4400 | X1: RAC-4416 | Y1: RAC-4432 | Z1: RAC-4448
A2: v3
A3: Space Information | D3: Network / Equipment Tree Information | J3: Network Information (MSTP and IP) | X3: Definitions and Templates | Z3: Parameters
A4: Site/Building/Floor (Required) | B4: Room Number (Optional) | C4: Leaf Space (e.g. Room) (Required) | D4: Device Name (Provided) | E4: Device FQR Reference (Provided) | F4: Device Description (Provided) | G4: Equipment Name (Required) | H4: Served By Equipment Name (Optional) | I4: Controller Part # (Optional) | J4: Engine Name (Provided) | K4: Trunk Name (Provided) | L4: Controller Host Name (Future) | M4: JCI MAC Address (Provided) | N4: IP Controller Number (Provided) | O4: ZIGBEE PAN Offset | P4: Instance # (BACoid) (Provided) | Q4: N2Address (Provided) | R4: DHCP Enabled (Provided) | S4: IP Address (Provided) | T4: Subnet Mask (Provided) | U4: IP Router (Provided) | V4: ETH-1 (Optional) | W4: ETH-2 (Optional) | X4: Equipment Definition Name (Provided) | Y4: Controller Template Name (Not Used) | Z4: SA-AREA | AA4: SA-KFACTOR | AB4: CLG-MAXFLOW | AC4: CLGOCC-MINFLOW | AD4: HTGOCC-MINFLOW
D5: Attribute ID | Z5: AV3111 | AA5: AV3112 | AB5: AV3108 | AC5: AV3109 | AD5: AV3110
D6: Attribute Type | Z6: Default Value | AA6: Default Value | AB6: Default Value | AC6: Default Value | AD6: Default Value

Sheet New Site Examples
A1: RAC-4096 | B1: RAC-4112 | C1: RAC-4128 | D1: RAC-4144 | E1: RAC-4160 | F1: RAC-4166 | G1: RAC-4170 | H1: RAC-4176 | I1: RAC-4192 | J1: RAC-4208 | K1: RAC-4224 | L1: RAC-4240 | M1: RAC-4256 | N1: RAC-4272 | O1: RAC-4288 | P1: RAC-4304 | Q1: RAC-4311 | R1: RAC-4320 | S1: RAC-4336 | T1: RAC-4352 | U1: RAC-4368 | V1: RAC-4384 | W1: RAC-4400 | X1: RAC-4416 | Y1: RAC-4432 | Z1: RAC-4448
A2: v3
A3: Space Information | D3: All Items / Equipment Tree Information | J3: Network Information (MSTP and IP) | X3: Definitions and Templates | Z3: Parameters
A4: Site/Building/Floor (Required) | B4: Room Number (Optional) | C4: Leaf Space (e.g. Room) (Required) | D4: Device Name (Required) | E4: Device FQR Reference (Required) | F4: Device Description (Optional) | G4: Equipment Name | H4: Served By Equipment Name (Optional) | I4: Controller Part # (Optional) | J4: Engine Name (Required) | K4: Trunk Name (Required) | L4: Controller Host Name (Future) | M4: JCI MAC Address | N4: IP Controller Number | O4: ZIGBEE PAN Offset | P4: Instance # (BACoid) | Q4: N2Address | R4: DHCP Enabled | S4: IP Address | T4: Subnet Mask | U4: IP Router | V4: ETH-1 (Optional) | W4: ETH-2 (Optional) | X4: Equipment Definition Name (Optional) | Y4: Controller Template Name (Required)
D5: Attribute ID
D6: Attribute Type
A7: Central Plant Examples (MSTP Network Information) - For Central Plant Space Information, a sites campus name is typically entered under the Site/Bldg./Floor column and a Building Name entered as the Leaf Space. - For All Items / Equipment Tree Information, the Device and Equipment Names can be simple but you do have the option to create a more unique FQR Reference name so the information displayed in SMP views is more detailed. - There are typically no Served By Equipment Names for Central Plants unless the boilers, chillers, pumps etc. are created as unique Equipment instances after the Plant System Equipment is created. - Remember to setup the Point Name Display attributes in the Controller Templates to match the desired Point Naming strategy for the site. - It is reccommended that you create unique names for the Equipment and Controller Templates for Central Plants because they are typically not reused on other plant systems.
A8: JCI University | C8: Training | D8: NCE-1-Integrated-04 | E8: Chiller Plant | G8: Chiller Plant | I8: NCE | J8: NCE-1 | K8: Field Bus MSTP1 | M8: 4 | X8: Chiller Plant-CPO-ED | Y8: Chiller Plant-CPO-CT
A9: JCI University | C9: Training | D9: FAC-NCE-1-1-05 | E9: Hot Water Plant | G9: Hot Water Plant | I9: FAC-1632 | J9: NCE-1 | K9: Field Bus MSTP1 | M9: 5 | X9: HWS-ED | Y9: HWS-CT
A10: Air Handling Unit Example (MSTP Network Information) - For AHU Space Information, a floor or building becomes the Leaf Space. - For All Items / Equipment Tree Information, the Device and Equipment Names can be simple but you do have the option to create a more unique FQR Reference name so the information displayed in SMP views is more detailed. - You have the option to add 1 Served By Equipment Name in the template for one of the Central Plants. Other Central Plants serving the AHUs will have to be added manaually after the Rapid Archive Process is performed. - Remember to setup the Point Name Display attributes in the Controller Template to match the desired Point Naming strategy for the site. - It is reccommended that you try to reuse a common Equipment Definition for all AHUs of the same basic Mechanical Equipment Type even if the Controller Templates / CAF Files for each AHU may be slightly different.
A11: JCI University/Training | C11: Floor 1 | D11: FAC-NAE1-1-06-MASP | E11: FAC-NAE1-1-06-MASP | G11: AHU-MASP-1 | H11: Chiller Plant &&Hot Water Plant | I11: FAC-1632 | J11: NAE-1 | K11: Field Bus MSTP1 | M11: 6 | X11: AHU-MASD-ED | Y11: AHU-MASD
